<div class="errorsExecptions-block">
	<div class="n-nav-strip clearfix">
		<a href="#osFileMethods" class="pull-left green">
			<span class="glyphicon glyphicon-arrow-left gray"></span>
			Python3 OS
		</a>
		<a href="#class" class="pull-right green">
			Python3 面向对象
			<span class="glyphicon glyphicon-arrow-right gray"></span>
		</a>
	</div>
	<div class="n-block n-border-b">
		<h1 class="n-h1">
			Python3 <span class="green">错误和异常</span>
		</h1>
		<p>作为Python初学者，在刚学习Python编程时，经常会看到一些报错信息，在前面我们没有提及，这章节我们会专门介绍。</p>
		<p>Python有两种错误很容易辨认：语法错误和异常。</p>
		<h2 class="n-h2">语法错误</h2>
		<p>Python 的语法错误或者称之为解析错，是初学者经常碰到的，如下实例</p>
		<div class="n-example">
			<pre><code>>>> while True print('Hello world')
  File "&lt;stdin&gt;", line 1, in ?
    while True print('Hello world')
                   ^
SyntaxError: invalid syntax</code></pre>
		</div>
		<p>这个例子中，函数 print() 被检查到有错误，是它前面缺少了一个冒号（:）。</p>
		<p>语法分析器指出了出错的一行，并且在最先找到的错误的位置标记了一个小小的箭头。</p>
		<h2 class="n-h2">异常</h2>
		<p>即便Python程序的语法是正确的，在运行它的时候，也有可能发生错误。运行期检测到的错误被称为异常。</p>
		<p>大多数的异常都不会被程序处理，都以错误信息的形式展现在这里:</p>
		<div class="n-example">
			<pre><code>>>> 10 * (1/0)
Traceback (most recent call last):
  File "&lt;stdin&gt;", line 1, in ?
ZeroDivisionError: division by zero
>>> 4 + spam*3
Traceback (most recent call last):
  File "&lt;stdin&gt;", line 1, in ?
NameError: name 'spam' is not defined
>>> '2' + 2
Traceback (most recent call last):
  File "&lt;stdin&gt;", line 1, in ?
TypeError: Can't convert 'int' object to str implicitly</code></pre>
		</div>
		<p>异常以不同的类型出现，这些类型都作为信息的一部分打印出来: 例子中的类型有 ZeroDivisionError，NameError 和 TypeError。 </p>
		<p>错误信息的前面部分显示了异常发生的上下文，并以调用栈的形式显示具体信息。 </p>
		<h2 class="n-h2">异常处理</h2>
		<p>以下例子中，让用户输入一个合法的整数，但是允许用户中断这个程序（使用 Control-C 或者操作系统提供的方法）。用户中断的信息会引发一个 KeyboardInterrupt 异常。 </p>
		<div class="n-example">
			<pre><code>>>> while True:
        try:
            x = int(input("Please enter a number: "))
            break
        except ValueError:
            print("Oops!  That was no valid number.  Try again   ")</code></pre>
		</div>
		<p>try语句按照如下方式工作；</p>
		<ul>
			<li>首先，执行try子句（在关键字try和关键字except之间的语句）</li>
			<li>如果没有异常发生，忽略except子句，try子句执行后结束。</li>
			<li>如果在执行try子句的过程中发生了异常，那么try子句余下的部分将被忽略。如果异常的类型和 except 之后的名称相符，那么对应的except子句将被执行。最后执行 try 语句之后的代码。</li>
			<li>如果一个异常没有与任何的except匹配，那么这个异常将会传递给上层的try中。</li>
		</ul>
		<p>一个 try 语句可能包含多个except子句，分别来处理不同的特定的异常。最多只有一个分支会被执行。</p>
		<p>处理程序将只针对对应的try子句中的异常进行处理，而不是其他的 try 的处理程序中的异常。</p>
		<p>一个except子句可以同时处理多个异常，这些异常将被放在一个括号里成为一个元组，例如: </p>
		<pre> except (RuntimeError, TypeError, NameError):
        pass</pre>
        <p>最后一个except子句可以忽略异常的名称，它将被当作通配符使用。你可以使用这种方法打印一个错误信息，然后再次把异常抛出。</p>
        <div class="n-example">
			<pre><code>import sys

try:
    f = open('myfile.txt')
    s = f.readline()
    i = int(s.strip())
except OSError as err:
    print("OS error: {0}".format(err))
except ValueError:
    print("Could not convert data to an integer.")
except:
    print("Unexpected error:", sys.exc_info()[0])
    raise</code></pre>
		</div>
		<p>使用 else 子句比把所有的语句都放在 try 子句里面要好，这样可以避免一些意想不到的、而except又没有捕获的异常。</p>
		<p>异常处理并不仅仅处理那些直接发生在try子句中的异常，而且还能处理子句中调用的函数（甚至间接调用的函数）里抛出的异常。例如:</p>
		<div class="n-example">
			<pre><code>>>> def this_fails():
        x = 1/0
   
>>> try:
        this_fails()
    except ZeroDivisionError as err:
        print('Handling run-time error:', err)
   
Handling run-time error: int division or modulo by zero</code></pre>
		</div>
	</div>
	<div class="n-block n-border-b">
		<h2 class="n-h2">抛出异常</h2>
		<p>Python 使用 raise 语句抛出一个指定的异常。例如:</p>
		<div class="n-example">
			<pre><code>>>> raise NameError('HiThere')
Traceback (most recent call last):
  File "&lt;stdin&gt;", line 1, in ?
NameError: HiThere</code></pre>
		</div>
		<p>raise 唯一的一个参数指定了要被抛出的异常。它必须是一个异常的实例或者是异常的类（也就是 Exception 的子类）。</p>
		<p>如果你只想知道这是否抛出了一个异常，并不想去处理它，那么一个简单的 raise 语句就可以再次把它抛出。</p>
		<div class="n-example">
			<pre><code>>>> try:
        raise NameError('HiThere')
    except NameError:
        print('An exception flew by!')
        raise
   
An exception flew by!
Traceback (most recent call last):
  File "&lt;stdin&gt;", line 2, in ?
NameError: HiThere</code></pre>
		</div>
	</div>
	<div class="n-block n-border-b">
		<h2 class="n-h2">用户自定义异常</h2>
		<p>你可以通过创建一个新的exception类来拥有自己的异常。异常应该继承自 Exception 类，或者直接继承，或者间接继承，例如:</p>
		<div class="n-example">
			<pre><code>>>> class MyError(Exception):
        def __init__(self, value):
            self.value = value
        def __str__(self):
            return repr(self.value)
   
>>> try:
        raise MyError(2*2)
    except MyError as e:
        print('My exception occurred, value:', e.value)
   
My exception occurred, value: 4
>>> raise MyError('oops!')
Traceback (most recent call last):
  File "&lt;stdin&gt;", line 1, in ?
__main__.MyError: 'oops!'</code></pre>
		</div>
		<p>在这个例子中，类 Exception 默认的 __init__() 被覆盖。</p>
		<p>当创建一个模块有可能抛出多种不同的异常时，一种通常的做法是为这个包建立一个基础异常类，然后基于这个基础类为不同的错误情况创建不同的子类:</p>
		<div class="n-example">
			<pre><code>class Error(Exception):
    """Base class for exceptions in this module."""
    pass

class InputError(Error):
    """Exception raised for errors in the input.

    Attributes:
        expression -- input expression in which the error occurred
        message -- explanation of the error
    """

    def __init__(self, expression, message):
        self.expression = expression
        self.message = message

class TransitionError(Error):
    """Raised when an operation attempts a state transition that's not
    allowed.

    Attributes:
        previous -- state at beginning of transition
        next -- attempted new state
        message -- explanation of why the specific transition is not allowed
    """

    def __init__(self, previous, next, message):
        self.previous = previous
        self.next = next
        self.message = message</code></pre>
		</div>
		<p>大多数的异常的名字都以"Error"结尾，就跟标准的异常命名一样。</p>
	</div>
	<div class="n-block n-border-b">
		<h2 class="n-h2">定义清理行为</h2>
		<p>try 语句还有另外一个可选的子句，它定义了无论在任何情况下都会执行的清理行为。 例如:</p>
		<div class="n-example">
			<pre><code>>>> try:
...     raise KeyboardInterrupt
... finally:
...     print('Goodbye, world!')
... 
Goodbye, world!
Traceback (most recent call last):
  File "&lt;stdin&gt;", line 2, in &lt;module&gt;
KeyboardInterrupt</code></pre>
		</div>
		<p>以上例子不管 try 子句里面有没有发生异常，finally 子句都会执行。</p>
		<p>如果一个异常在 try 子句里（或者在 except 和 else 子句里）被抛出，而又没有任何的 except 把它截住，那么这个异常会在 finally 子句执行后再次被抛出。</p>
		<p>下面是一个更加复杂的例子（在同一个 try 语句里包含 except 和 finally 子句）:</p>
		<div class="n-example">
			<pre><code>>>> def divide(x, y):
        try:
            result = x / y
        except ZeroDivisionError:
            print("division by zero!")
        else:
            print("result is", result)
        finally:
            print("executing finally clause")
   
>>> divide(2, 1)
result is 2.0
executing finally clause
>>> divide(2, 0)
division by zero!
executing finally clause
>>> divide("2", "1")
executing finally clause
Traceback (most recent call last):
  File "&lt;stdin&gt;", line 1, in ?
  File "&lt;stdin&gt;", line 3, in divide
TypeError: unsupported operand type(s) for /: 'str' and 'str'</code></pre>
		</div>
	</div>
	<div class="n-block n-border-b">
		<h2 class="n-h2">预定义的清理行为</h2>
		<p>一些对象定义了标准的清理行为，无论系统是否成功的使用了它，一旦不需要它了，那么这个标准的清理行为就会执行。</p>
		<p>这面这个例子展示了尝试打开一个文件，然后把内容打印到屏幕上: </p>
		<div class="n-example">
			<pre><code>for line in open("myfile.txt"):
    print(line, end="")</code></pre>
		</div>
		<p>以上这段代码的问题是，当执行完毕后，文件会保持打开状态，并没有被关闭。</p>
		<p>关键词 with 语句就可以保证诸如文件之类的对象在使用完之后一定会正确的执行他的清理方法:</p>
		<div class="n-example">
			<pre><code>with open("myfile.txt") as f:
    for line in f:
        print(line, end="")</code></pre>
		</div>
		<p>以上这段代码执行完毕后，就算在处理过程中出问题了，文件 f 总是会关闭。 </p>
	</div>
	<div class="n-nav-strip clearfix">
		<a href="#osFileMethods" class="pull-left green">
			<span class="glyphicon glyphicon-arrow-left gray"></span>
			Python3 OS
		</a>
		<a href="#class" class="pull-right green">
			Python3 面向对象
			<span class="glyphicon glyphicon-arrow-right gray"></span>
		</a>
	</div>
</div>